---
title: 以下代码输出什么，为什么
date: 2021-03-27
categories: 
 - 面试
tags:
 - 输出什么
sidebar: 'auto'
---

> 题目来源<https://jsgodroad.com/questions/detail?id=7>

``` js
try {
  (async function() { a().b().c() })()
} catch(err) {
  console.log(`执行错误：${err.message}`)
}
```

1. 输出结果为`Uncaught (in promise) ReferenceError: a is not defined`
2. 因为`try``catch`只能捕获同步运行出错的代码，而在该`try`块中执行了一个异步的函数，所以不会被catch到，将代码改为
``` js
try {
  await (async function () { a().b().c() })()
} catch (err) {
  console.log(`执行错误：${err.message}`)
}
```
在自执行函数加上`await`关键字后会将异步任务转化为同步执行，这样就能在`catch`中捕获到错误，会输出`执行错误：a is not defined`