---
title: 以下代码输出什么，为什么
date: 2021-03-28
categories: 
 - 面试
tags:
 - 输出什么
sidebar: 'auto'
---

> 题目来源<https://jsgodroad.com/questions/detail?id=8>

``` js
try {
  let a = 0
  ;(async function() {
    a += 1
    console.log('inner', a)
    throw Error('123')
  })()
  console.log('outer', a)
} catch (err) {
  console.log('执行错误：', err)
}
```

1. 执行结果 `inner 1` `outer 1` `Uncaught (in promise) Error: 123`

2. 虽然`async`函数会将编译成`Promise`，但是在`async`函数内部只要没遇见`await`都是同步执行的，只有`await`后面的代码才是异步执行，上面代码中，async函数内部同步执行`a+=1`此时a变成1然后输出`inner 1`，接着`throw Error('123')`，也就相当于`Promise.reject()`，被reject掉之后进入微任务队列中，此时同步代码还未执行完，接着执行`outer 1`，同步代码执行完成，执行微任务，输出`Uncaught (in promise) Error: 123`